[2024-03-29T16:58:44.976+0000] {taskinstance.py:1957} INFO - Dependencies all met for dep_context=non-requeueable deps ti=<TaskInstance: demo_retry_and_alert.get_data_from_api manual__2024-03-29T16:58:29.597481+00:00 [queued]>
[2024-03-29T16:58:44.984+0000] {taskinstance.py:1957} INFO - Dependencies all met for dep_context=requeueable deps ti=<TaskInstance: demo_retry_and_alert.get_data_from_api manual__2024-03-29T16:58:29.597481+00:00 [queued]>
[2024-03-29T16:58:44.984+0000] {taskinstance.py:2171} INFO - Starting attempt 3 of 4
[2024-03-29T16:58:44.995+0000] {taskinstance.py:2192} INFO - Executing <Task(PythonOperator): get_data_from_api> on 2024-03-29 16:58:29.597481+00:00
[2024-03-29T16:58:45.000+0000] {standard_task_runner.py:60} INFO - Started process 2479 to run task
[2024-03-29T16:58:45.005+0000] {standard_task_runner.py:87} INFO - Running: ['***', 'tasks', 'run', 'demo_retry_and_alert', 'get_data_from_api', 'manual__2024-03-29T16:58:29.597481+00:00', '--job-id', '23', '--raw', '--subdir', 'DAGS_FOLDER/demo_retry_and_alert.py', '--cfg-path', '/tmp/tmpdl7daaxr']
[2024-03-29T16:58:45.012+0000] {standard_task_runner.py:88} INFO - Job 23: Subtask get_data_from_api
[2024-03-29T16:58:45.031+0000] {logging_mixin.py:188} WARNING - /home/***/.local/lib/python3.8/site-packages/***/settings.py:195 DeprecationWarning: The sql_alchemy_conn option in [core] has been moved to the sql_alchemy_conn option in [database] - the old setting has been used, but please update your config.
[2024-03-29T16:58:45.059+0000] {task_command.py:423} INFO - Running <TaskInstance: demo_retry_and_alert.get_data_from_api manual__2024-03-29T16:58:29.597481+00:00 [running]> on host c4cb237119ff
[2024-03-29T16:58:45.127+0000] {taskinstance.py:2481} INFO - Exporting env vars: AIRFLOW_CTX_DAG_EMAIL='dom@email.io' AIRFLOW_CTX_DAG_OWNER='domwatcharin' AIRFLOW_CTX_DAG_ID='demo_retry_and_alert' AIRFLOW_CTX_TASK_ID='get_data_from_api' AIRFLOW_CTX_EXECUTION_DATE='2024-03-29T16:58:29.597481+00:00' AIRFLOW_CTX_TRY_NUMBER='3' AIRFLOW_CTX_DAG_RUN_ID='manual__2024-03-29T16:58:29.597481+00:00'
[2024-03-29T16:58:45.128+0000] {taskinstance.py:2699} ERROR - Task failed with exception
Traceback (most recent call last):
  File "/home/airflow/.local/lib/python3.8/site-packages/airflow/models/taskinstance.py", line 433, in _execute_task
    result = execute_callable(context=context, **execute_callable_kwargs)
  File "/home/airflow/.local/lib/python3.8/site-packages/airflow/operators/python.py", line 199, in execute
    return_value = self.execute_callable()
  File "/home/airflow/.local/lib/python3.8/site-packages/airflow/operators/python.py", line 216, in execute_callable
    return self.python_callable(*self.op_args, **self.op_kwargs)
  File "/opt/airflow/dags/demo_retry_and_alert.py", line 20, in _get_data_from_api
    raise ValueError()
ValueError
[2024-03-29T16:58:45.137+0000] {taskinstance.py:1138} INFO - Marking task as UP_FOR_RETRY. dag_id=demo_retry_and_alert, task_id=get_data_from_api, execution_date=20240329T165829, start_date=20240329T165844, end_date=20240329T165845
[2024-03-29T16:58:45.149+0000] {logging_mixin.py:188} WARNING - /home/***/.local/lib/python3.8/site-packages/***/utils/email.py:154 RemovedInAirflow3Warning: Fetching SMTP credentials from configuration variables will be deprecated in a future release. Please set credentials using a connection instead.
[2024-03-29T16:58:45.150+0000] {configuration.py:1046} WARNING - section/key [smtp/smtp_user] not found in config
[2024-03-29T16:58:45.150+0000] {email.py:270} INFO - Email alerting: attempt 1
[2024-03-29T16:58:45.157+0000] {email.py:281} INFO - Sent an alert email to ['dom@email.io']
[2024-03-29T16:58:45.169+0000] {demo_retry_and_alert.py:10} INFO - {'conf': <***.configuration.AirflowConfigParser object at 0x7ffffc1661f0>, 'dag': <DAG: demo_retry_and_alert>, 'dag_run': <DagRun demo_retry_and_alert @ 2024-03-29 16:58:29.597481+00:00: manual__2024-03-29T16:58:29.597481+00:00, state:running, queued_at: 2024-03-29 16:58:29.729203+00:00. externally triggered: True>, 'data_interval_end': DateTime(2024, 3, 29, 16, 58, 29, 597481, tzinfo=Timezone('UTC')), 'data_interval_start': DateTime(2024, 3, 29, 16, 58, 29, 597481, tzinfo=Timezone('UTC')), 'ds': '2024-03-29', 'ds_nodash': '20240329', 'execution_date': DateTime(2024, 3, 29, 16, 58, 29, 597481, tzinfo=Timezone('UTC')), 'expanded_ti_count': None, 'inlets': [], 'logical_date': DateTime(2024, 3, 29, 16, 58, 29, 597481, tzinfo=Timezone('UTC')), 'macros': <module '***.macros' from '/home/***/.local/lib/python3.8/site-packages/***/macros/__init__.py'>, 'next_ds': '2024-03-29', 'next_ds_nodash': '20240329', 'next_execution_date': DateTime(2024, 3, 29, 16, 58, 29, 597481, tzinfo=Timezone('UTC')), 'outlets': [], 'params': {}, 'prev_data_interval_start_success': None, 'prev_data_interval_end_success': None, 'prev_ds': '2024-03-29', 'prev_ds_nodash': '20240329', 'prev_execution_date': DateTime(2024, 3, 29, 16, 58, 29, 597481, tzinfo=Timezone('UTC')), 'prev_execution_date_success': None, 'prev_start_date_success': None, 'prev_end_date_success': None, 'run_id': 'manual__2024-03-29T16:58:29.597481+00:00', 'task': <Task(PythonOperator): get_data_from_api>, 'task_instance': <TaskInstance: demo_retry_and_alert.get_data_from_api manual__2024-03-29T16:58:29.597481+00:00 [up_for_retry]>, 'task_instance_key_str': 'demo_retry_and_alert__get_data_from_api__20240329', 'test_mode': False, 'ti': <TaskInstance: demo_retry_and_alert.get_data_from_api manual__2024-03-29T16:58:29.597481+00:00 [up_for_retry]>, 'tomorrow_ds': '2024-03-30', 'tomorrow_ds_nodash': '20240330', 'triggering_dataset_events': <Proxy at 0x7ffff231e0c0 with factory <function _get_template_context.<locals>.get_triggering_events at 0x7ffff2316790>>, 'ts': '2024-03-29T16:58:29.597481+00:00', 'ts_nodash': '20240329T165829', 'ts_nodash_with_tz': '20240329T165829.597481+0000', 'var': {'json': None, 'value': None}, 'conn': None, 'yesterday_ds': '2024-03-28', 'yesterday_ds_nodash': '20240328', 'templates_dict': None, 'exception': ValueError()}
[2024-03-29T16:58:45.171+0000] {demo_retry_and_alert.py:11} ERROR - Cannot call API at this moment. Wait for retrying..
[2024-03-29T16:58:45.206+0000] {standard_task_runner.py:107} ERROR - Failed to execute job 23 for task get_data_from_api (; 2479)
[2024-03-29T16:58:45.226+0000] {local_task_job_runner.py:234} INFO - Task exited with return code 1
[2024-03-29T16:58:45.263+0000] {taskinstance.py:3281} INFO - 0 downstream tasks scheduled from follow-on schedule check
