[2024-03-29T17:01:44.064+0000] {taskinstance.py:1957} INFO - Dependencies all met for dep_context=non-requeueable deps ti=<TaskInstance: demo_hooks.query_data manual__2024-03-29T17:01:40.251776+00:00 [queued]>
[2024-03-29T17:01:44.088+0000] {taskinstance.py:1957} INFO - Dependencies all met for dep_context=requeueable deps ti=<TaskInstance: demo_hooks.query_data manual__2024-03-29T17:01:40.251776+00:00 [queued]>
[2024-03-29T17:01:44.089+0000] {taskinstance.py:2171} INFO - Starting attempt 1 of 1
[2024-03-29T17:01:44.178+0000] {taskinstance.py:2192} INFO - Executing <Task(PythonOperator): query_data> on 2024-03-29 17:01:40.251776+00:00
[2024-03-29T17:01:44.192+0000] {standard_task_runner.py:60} INFO - Started process 3219 to run task
[2024-03-29T17:01:44.201+0000] {standard_task_runner.py:87} INFO - Running: ['***', 'tasks', 'run', 'demo_hooks', 'query_data', 'manual__2024-03-29T17:01:40.251776+00:00', '--job-id', '43', '--raw', '--subdir', 'DAGS_FOLDER/demo_hooks.py', '--cfg-path', '/tmp/tmp68trlyz8']
[2024-03-29T17:01:44.215+0000] {standard_task_runner.py:88} INFO - Job 43: Subtask query_data
[2024-03-29T17:01:44.249+0000] {logging_mixin.py:188} WARNING - /home/***/.local/lib/python3.8/site-packages/***/settings.py:195 DeprecationWarning: The sql_alchemy_conn option in [core] has been moved to the sql_alchemy_conn option in [database] - the old setting has been used, but please update your config.
[2024-03-29T17:01:44.322+0000] {task_command.py:423} INFO - Running <TaskInstance: demo_hooks.query_data manual__2024-03-29T17:01:40.251776+00:00 [running]> on host c4cb237119ff
[2024-03-29T17:01:44.444+0000] {taskinstance.py:2481} INFO - Exporting env vars: AIRFLOW_CTX_DAG_OWNER='domwatcharin' AIRFLOW_CTX_DAG_ID='demo_hooks' AIRFLOW_CTX_TASK_ID='query_data' AIRFLOW_CTX_EXECUTION_DATE='2024-03-29T17:01:40.251776+00:00' AIRFLOW_CTX_TRY_NUMBER='1' AIRFLOW_CTX_DAG_RUN_ID='manual__2024-03-29T17:01:40.251776+00:00'
[2024-03-29T17:01:44.511+0000] {taskinstance.py:2699} ERROR - Task failed with exception
Traceback (most recent call last):
  File "/home/airflow/.local/lib/python3.8/site-packages/airflow/models/taskinstance.py", line 433, in _execute_task
    result = execute_callable(context=context, **execute_callable_kwargs)
  File "/home/airflow/.local/lib/python3.8/site-packages/airflow/operators/python.py", line 199, in execute
    return_value = self.execute_callable()
  File "/home/airflow/.local/lib/python3.8/site-packages/airflow/operators/python.py", line 216, in execute_callable
    return self.python_callable(*self.op_args, **self.op_kwargs)
  File "/opt/airflow/dags/demo_hooks.py", line 14, in _query_data
    connection = pg_hook.get_conn()
  File "/home/airflow/.local/lib/python3.8/site-packages/airflow/providers/postgres/hooks/postgres.py", line 128, in get_conn
    conn = deepcopy(self.connection or self.get_connection(conn_id))
  File "/home/airflow/.local/lib/python3.8/site-packages/airflow/hooks/base.py", line 82, in get_connection
    conn = Connection.get_connection_from_secrets(conn_id)
  File "/home/airflow/.local/lib/python3.8/site-packages/airflow/models/connection.py", line 479, in get_connection_from_secrets
    raise AirflowNotFoundException(f"The conn_id `{conn_id}` isn't defined")
airflow.exceptions.AirflowNotFoundException: The conn_id `***_metastore` isn't defined
[2024-03-29T17:01:44.527+0000] {taskinstance.py:1138} INFO - Marking task as FAILED. dag_id=demo_hooks, task_id=query_data, execution_date=20240329T170140, start_date=20240329T170144, end_date=20240329T170144
[2024-03-29T17:01:44.545+0000] {standard_task_runner.py:107} ERROR - Failed to execute job 43 for task query_data (The conn_id `***_metastore` isn't defined; 3219)
[2024-03-29T17:01:44.591+0000] {local_task_job_runner.py:234} INFO - Task exited with return code 1
[2024-03-29T17:01:44.639+0000] {taskinstance.py:3281} INFO - 0 downstream tasks scheduled from follow-on schedule check
