[2024-03-28T17:21:57.450+0000] {taskinstance.py:1957} INFO - Dependencies all met for dep_context=non-requeueable deps ti=<TaskInstance: cryptocurrency_data_pipeline.merge_import_into_final_table scheduled__2024-01-10T00:00:00+00:00 [queued]>
[2024-03-28T17:22:08.482+0000] {taskinstance.py:1957} INFO - Dependencies all met for dep_context=requeueable deps ti=<TaskInstance: cryptocurrency_data_pipeline.merge_import_into_final_table scheduled__2024-01-10T00:00:00+00:00 [queued]>
[2024-03-28T17:22:09.740+0000] {taskinstance.py:2171} INFO - Starting attempt 1 of 1
[2024-03-28T17:22:29.903+0000] {taskinstance.py:2192} INFO - Executing <Task(PostgresOperator): merge_import_into_final_table> on 2024-01-10 00:00:00+00:00
[2024-03-28T17:22:31.259+0000] {standard_task_runner.py:60} INFO - Started process 600 to run task
[2024-03-28T17:22:33.817+0000] {standard_task_runner.py:87} INFO - Running: ['***', 'tasks', 'run', 'cryptocurrency_data_pipeline', 'merge_import_into_final_table', 'scheduled__2024-01-10T00:00:00+00:00', '--job-id', '71', '--raw', '--subdir', 'DAGS_FOLDER/cryptocurrency_data_pipeline.py', '--cfg-path', '/tmp/tmpzf0wj9xw']
[2024-03-28T17:22:35.583+0000] {standard_task_runner.py:88} INFO - Job 71: Subtask merge_import_into_final_table
[2024-03-28T17:23:05.527+0000] {logging_mixin.py:188} WARNING - /home/***/.local/lib/python3.8/site-packages/***/settings.py:195 DeprecationWarning: The sql_alchemy_conn option in [core] has been moved to the sql_alchemy_conn option in [database] - the old setting has been used, but please update your config.
[2024-03-28T17:23:50.954+0000] {task_command.py:423} INFO - Running <TaskInstance: cryptocurrency_data_pipeline.merge_import_into_final_table scheduled__2024-01-10T00:00:00+00:00 [running]> on host de9dce8fd105
[2024-03-28T17:23:54.064+0000] {job.py:213} ERROR - Job heartbeat got an exception
Traceback (most recent call last):
  File "/home/airflow/.local/lib/python3.8/site-packages/sqlalchemy/engine/base.py", line 3371, in _wrap_pool_connect
    return fn()
  File "/home/airflow/.local/lib/python3.8/site-packages/sqlalchemy/pool/base.py", line 327, in connect
    return _ConnectionFairy._checkout(self)
  File "/home/airflow/.local/lib/python3.8/site-packages/sqlalchemy/pool/base.py", line 894, in _checkout
    fairy = _ConnectionRecord.checkout(pool)
  File "/home/airflow/.local/lib/python3.8/site-packages/sqlalchemy/pool/base.py", line 493, in checkout
    rec = pool._do_get()
  File "/home/airflow/.local/lib/python3.8/site-packages/sqlalchemy/pool/impl.py", line 256, in _do_get
    return self._create_connection()
  File "/home/airflow/.local/lib/python3.8/site-packages/sqlalchemy/pool/base.py", line 273, in _create_connection
    return _ConnectionRecord(self)
  File "/home/airflow/.local/lib/python3.8/site-packages/sqlalchemy/pool/base.py", line 388, in __init__
    self.__connect()
  File "/home/airflow/.local/lib/python3.8/site-packages/sqlalchemy/pool/base.py", line 691, in __connect
    pool.logger.debug("Error on connect(): %s", e)
  File "/home/airflow/.local/lib/python3.8/site-packages/sqlalchemy/util/langhelpers.py", line 70, in __exit__
    compat.raise_(
  File "/home/airflow/.local/lib/python3.8/site-packages/sqlalchemy/util/compat.py", line 211, in raise_
    raise exception
  File "/home/airflow/.local/lib/python3.8/site-packages/sqlalchemy/pool/base.py", line 686, in __connect
    self.dbapi_connection = connection = pool._invoke_creator(self)
  File "/home/airflow/.local/lib/python3.8/site-packages/sqlalchemy/engine/create.py", line 574, in connect
    return dialect.connect(*cargs, **cparams)
  File "/home/airflow/.local/lib/python3.8/site-packages/sqlalchemy/engine/default.py", line 598, in connect
    return self.dbapi.connect(*cargs, **cparams)
  File "/home/airflow/.local/lib/python3.8/site-packages/psycopg2/__init__.py", line 122, in connect
    conn = _connect(dsn, connection_factory=connection_factory, **kwasync)
psycopg2.OperationalError: could not translate host name "***-metastore" to address: Temporary failure in name resolution


The above exception was the direct cause of the following exception:

Traceback (most recent call last):
  File "/home/airflow/.local/lib/python3.8/site-packages/airflow/jobs/job.py", line 187, in heartbeat
    self._merge_from(Job._fetch_from_db(self, session))
  File "/home/airflow/.local/lib/python3.8/site-packages/airflow/api_internal/internal_api_call.py", line 114, in wrapper
    return func(*args, **kwargs)
  File "/home/airflow/.local/lib/python3.8/site-packages/airflow/utils/session.py", line 76, in wrapper
    return func(*args, **kwargs)
  File "/home/airflow/.local/lib/python3.8/site-packages/airflow/jobs/job.py", line 308, in _fetch_from_db
    session.merge(job)
  File "/home/airflow/.local/lib/python3.8/site-packages/sqlalchemy/orm/session.py", line 3056, in merge
    return self._merge(
  File "/home/airflow/.local/lib/python3.8/site-packages/sqlalchemy/orm/session.py", line 3136, in _merge
    merged = self.get(
  File "/home/airflow/.local/lib/python3.8/site-packages/sqlalchemy/orm/session.py", line 2853, in get
    return self._get_impl(
  File "/home/airflow/.local/lib/python3.8/site-packages/sqlalchemy/orm/session.py", line 2975, in _get_impl
    return db_load_fn(
  File "/home/airflow/.local/lib/python3.8/site-packages/sqlalchemy/orm/loading.py", line 530, in load_on_pk_identity
    session.execute(
  File "/home/airflow/.local/lib/python3.8/site-packages/sqlalchemy/orm/session.py", line 1716, in execute
    conn = self._connection_for_bind(bind)
  File "/home/airflow/.local/lib/python3.8/site-packages/sqlalchemy/orm/session.py", line 1555, in _connection_for_bind
    return self._transaction._connection_for_bind(
  File "/home/airflow/.local/lib/python3.8/site-packages/sqlalchemy/orm/session.py", line 750, in _connection_for_bind
    conn = bind.connect()
  File "/home/airflow/.local/lib/python3.8/site-packages/sqlalchemy/future/engine.py", line 406, in connect
    return super(Engine, self).connect()
  File "/home/airflow/.local/lib/python3.8/site-packages/sqlalchemy/engine/base.py", line 3325, in connect
    return self._connection_cls(self, close_with_result=close_with_result)
  File "/home/airflow/.local/lib/python3.8/site-packages/sqlalchemy/engine/base.py", line 96, in __init__
    else engine.raw_connection()
  File "/home/airflow/.local/lib/python3.8/site-packages/sqlalchemy/engine/base.py", line 3404, in raw_connection
    return self._wrap_pool_connect(self.pool.connect, _connection)
  File "/home/airflow/.local/lib/python3.8/site-packages/sqlalchemy/engine/base.py", line 3374, in _wrap_pool_connect
    Connection._handle_dbapi_exception_noconnection(
  File "/home/airflow/.local/lib/python3.8/site-packages/sqlalchemy/engine/base.py", line 2208, in _handle_dbapi_exception_noconnection
    util.raise_(
  File "/home/airflow/.local/lib/python3.8/site-packages/sqlalchemy/util/compat.py", line 211, in raise_
    raise exception
  File "/home/airflow/.local/lib/python3.8/site-packages/sqlalchemy/engine/base.py", line 3371, in _wrap_pool_connect
    return fn()
  File "/home/airflow/.local/lib/python3.8/site-packages/sqlalchemy/pool/base.py", line 327, in connect
    return _ConnectionFairy._checkout(self)
  File "/home/airflow/.local/lib/python3.8/site-packages/sqlalchemy/pool/base.py", line 894, in _checkout
    fairy = _ConnectionRecord.checkout(pool)
  File "/home/airflow/.local/lib/python3.8/site-packages/sqlalchemy/pool/base.py", line 493, in checkout
    rec = pool._do_get()
  File "/home/airflow/.local/lib/python3.8/site-packages/sqlalchemy/pool/impl.py", line 256, in _do_get
    return self._create_connection()
  File "/home/airflow/.local/lib/python3.8/site-packages/sqlalchemy/pool/base.py", line 273, in _create_connection
    return _ConnectionRecord(self)
  File "/home/airflow/.local/lib/python3.8/site-packages/sqlalchemy/pool/base.py", line 388, in __init__
    self.__connect()
  File "/home/airflow/.local/lib/python3.8/site-packages/sqlalchemy/pool/base.py", line 691, in __connect
    pool.logger.debug("Error on connect(): %s", e)
  File "/home/airflow/.local/lib/python3.8/site-packages/sqlalchemy/util/langhelpers.py", line 70, in __exit__
    compat.raise_(
  File "/home/airflow/.local/lib/python3.8/site-packages/sqlalchemy/util/compat.py", line 211, in raise_
    raise exception
  File "/home/airflow/.local/lib/python3.8/site-packages/sqlalchemy/pool/base.py", line 686, in __connect
    self.dbapi_connection = connection = pool._invoke_creator(self)
  File "/home/airflow/.local/lib/python3.8/site-packages/sqlalchemy/engine/create.py", line 574, in connect
    return dialect.connect(*cargs, **cparams)
  File "/home/airflow/.local/lib/python3.8/site-packages/sqlalchemy/engine/default.py", line 598, in connect
    return self.dbapi.connect(*cargs, **cparams)
  File "/home/airflow/.local/lib/python3.8/site-packages/psycopg2/__init__.py", line 122, in connect
    conn = _connect(dsn, connection_factory=connection_factory, **kwasync)
sqlalchemy.exc.OperationalError: (psycopg2.OperationalError) could not translate host name "***-metastore" to address: Temporary failure in name resolution

(Background on this error at: https://sqlalche.me/e/14/e3q8)
[2024-03-28T17:23:58.714+0000] {job.py:221} ERROR - Job heartbeat failed with error. Scheduler is in unhealthy state
[2024-03-28T17:24:48.520+0000] {taskinstance.py:2481} INFO - Exporting env vars: AIRFLOW_CTX_DAG_EMAIL='dom@dataengineercafe.io' AIRFLOW_CTX_DAG_OWNER='domwatcharin' AIRFLOW_CTX_DAG_ID='cryptocurrency_data_pipeline' AIRFLOW_CTX_TASK_ID='merge_import_into_final_table' AIRFLOW_CTX_EXECUTION_DATE='2024-01-10T00:00:00+00:00' AIRFLOW_CTX_TRY_NUMBER='1' AIRFLOW_CTX_DAG_RUN_ID='scheduled__2024-01-10T00:00:00+00:00'
[2024-03-28T17:24:51.014+0000] {sql.py:276} INFO - Executing: 
            INSERT INTO cryptocurrency (
                timestamp,
                open,
                highest,
                lowest,
                closing,
                volume
            )
            SELECT
                timestamp,
                open,
                highest,
                lowest,
                closing,
                volume
            FROM
                cryptocurrency_import
            ON CONFLICT (timestamp)
            DO UPDATE SET
                open = EXCLUDED.open,
                highest = EXCLUDED.highest,
                lowest = EXCLUDED.lowest,
                closing = EXCLUDED.closing,
                volume = EXCLUDED.volume
        
[2024-03-28T17:25:06.735+0000] {base.py:83} INFO - Using connection ID '***' for task execution.
[2024-03-28T17:25:12.165+0000] {base.py:83} INFO - Using connection ID '***' for task execution.
[2024-03-28T17:25:13.341+0000] {sql.py:432} INFO - Running statement: 
            INSERT INTO cryptocurrency (
                timestamp,
                open,
                highest,
                lowest,
                closing,
                volume
            )
            SELECT
                timestamp,
                open,
                highest,
                lowest,
                closing,
                volume
            FROM
                cryptocurrency_import
            ON CONFLICT (timestamp)
            DO UPDATE SET
                open = EXCLUDED.open,
                highest = EXCLUDED.highest,
                lowest = EXCLUDED.lowest,
                closing = EXCLUDED.closing,
                volume = EXCLUDED.volume
        , parameters: None
[2024-03-28T17:25:13.762+0000] {sql.py:441} INFO - Rows affected: 144
[2024-03-28T17:25:17.760+0000] {taskinstance.py:1138} INFO - Marking task as SUCCESS. dag_id=cryptocurrency_data_pipeline, task_id=merge_import_into_final_table, execution_date=20240110T000000, start_date=20240328T172201, end_date=20240328T172517
[2024-03-28T17:25:30.770+0000] {local_task_job_runner.py:234} INFO - Task exited with return code 0
[2024-03-28T17:25:54.512+0000] {taskinstance.py:3281} INFO - 1 downstream tasks scheduled from follow-on schedule check
